Workbook

Sheet Data
A1: Pokémon | B1: Lvl. | C1: Type | D1: Berries | E1: Ingredient Level 1 | F1: Ingredient Level 30 | G1: Ingredient Level 60 | H1: Skill Level 10 | I1: Skill Level25 | J1: Skill Level 50 | K1: Skill Level 75 | L1: Skill Level 100 | M1: Nature | N1: Nature Positives | O1: Nature Negatives | P1: Berry Score | Q1: Ingredient Score | R1: Skill Score | S1: Team | T1: Totaal Score | U1: Advies | V1: Notities
A2: Pikachu | B2: 15 | C2: Electric | D2: =IF(C2="","",VLOOKUP(C2,Referentie!$A$2:$B$19,2,0)) -> Grepa | E2: Fancy Apple | F2: Warming Ginger | G2: Fancy Apple | H2: Inventory Up S | I2: Ingredient Finder S | J2: Inventory Up M | K2: Ingredient Finder M | L2: Skill Trigger S | M2: Modest | N2: =IF(M2="","",VLOOKUP(M2,Referentie!$G$2:$I$26,2,0)) -> Ingredient Finding | O2: =IF(M2="","",VLOOKUP(M2,Referentie!$G$2:$I$26,3,0)) -> Speed of Help | P2: =IF(A2="","", (IF(N2="Speed of Help",2,0)) + (IF(O2="Speed of Help",-2,0)) + (IF(N2="EXP Gains",1,0)) + (IF(O2="EXP Gains",-1,0)) + (COUNTIF(H2:L2,"Helping Speed S")*1) + (COUNTIF(H2:L2,"Helping Speed M")*2) + (COUNTIF(H2:L2,"Berry Finding S")*2) + (COUNTIF(H2:L2,"Helping Bonus")*1) + (IF(O2="Ingredient Finding",0,0)) + (IF(O2="Main Skill Chance",0,0)) ) -> -2 | Q2: =IF(A2="","", (IF(N2="Ingredient Finding",2,0)) + (IF(O2="Ingredient Finding",-2,0)) + (IF(N2="EXP Gains",1,0)) + (IF(O2="EXP Gains",-1,0)) + (COUNTIF(H2:L2,"Ingredient Finder S")*1) + (COUNTIF(H2:L2,"Ingredient Finder M")*2) + (COUNTIF(H2:L2,"Inventory Up S")*0.5) + (COUNTIF(H2:L2,"Inventory Up M")*1) + (COUNTIF(H2:L2,"Inventory Up L")*1.5) + (IF(E2=F2,1,0)) + (IF(F2=G2,1,0)) ) -> 6.5 | R2: =IF(A2="","", (IF(N2="Main Skill Chance",2,0)) + (IF(O2="Main Skill Chance",-2,0)) + (IF(N2="EXP Gains",1,0)) + (IF(O2="EXP Gains",-1,0)) + (COUNTIF(H2:L2,"Skill Trigger S")*1) + (COUNTIF(H2:L2,"Skill Trigger M")*2) + (COUNTIF(H2:L2,"Skill Level Up S")*1) + (COUNTIF(H2:L2,"Skill Level Up M")*2) + (COUNTIF(H2:L2,"Energy Recovery Bonus")*1.5) + (COUNTIF(H2:L2,"Sleep EXP Bonus")*1) + (COUNTIF(H2:L2,"Research EXP Bonus")*1) ) -> 1 | S2: =IF(A2="","", IF(AND(P2<=1, Q2<=1, R2<=1), "Bench", IF(AND(P2>=Q2, P2>=R2), "Berry", IF(AND(Q2>=P2, Q2>=R2), "Ingredient", "Skill"))) ) -> Ingredient | T2: =IF(A2="","", MAX(P2,Q2,R2) + IF(OR(N2="Speed of Help",N2="Ingredient Finding",N2="Main Skill Chance"),1,0) + IF(N2="Neutral",0, IF(O2="Neutral",0.5,0)) + IF(B2>=10,0.5,0) ) -> 8 | U2: =IF(A2="","", IF(T2>=7, "⭐ Keep", IF(T2>=5, "📈 Level Up", IF(T2>=3, "🤔 Bench", "❌ Transfer"))) ) -> ⭐ Keep | V2: =IF(A2="","", _xlfn.TEXTJOIN("; ",TRUE, IF(A2="Pikachu","Evolve naar Raichu = snelste berry helper!",""), IF(A2="Pichu","Evolve → Pikachu → Raichu (top berry)",""), IF(A2="Eevee","Sylveon (skill) of Jolteon (berry) = top evoluties",""), IF(A2="Igglybuff","Evolve → Wigglytuff = Energy for Everyone S (top skill!)",""), IF(A2="Squirtle","Kanto starter: 2x ingrediënten + Ingredient Magnet S",""), IF(A2="Charmander","Evolve → Charizard = snelle berry+ingredient verzamelaar",""), IF(A2="Bulbasaur","Kanto starter: 2x ingrediënten + Ingredient Magnet S",""), IF(A2="Growlithe","Evolve → Arcanine = sterke all-rounder",""), IF(A2="Mareep","Evolve → Ampharos = hoge frequentie + waardevolle ingrediënten",""), IF(A2="Spheal","Evolve → Walrein = key voor Snowdrop Tundra (berry+ingr)",""), IF(A2="Riolu","Evolve → Lucario = sterke fighter",""), IF(A2="Togepi","Let op: Togekiss Metronome is onbetrouwbaar",""), IF(A2="Totodile","Evolve → Feraligatr = top berry voor Cyan Beach",""), IF(A2="Magnemite","Evolve → Magnezone = sterke skill helper",""), IF(A2="Ivysaur","Evolve → Venusaur = 2x ingrediënten specialist",""), IF(OR(N2="Neutral",O2="Neutral"),"Neutrale nature = ok maar niet ideaal",""), IF(AND(N2="Speed of Help",OR(S2="Berry",S2="Ingredient")),"Perfecte nature voor "&S2&" team!",""), IF(AND(N2="Ingredient Finding",S2="Ingredient"),"Perfecte nature voor Ingredient team!",""), IF(AND(N2="Main Skill Chance",S2="Skill"),"Perfecte nature voor Skill team!",""), IF(AND(O2="Speed of Help",S2="Berry"),"Let op: Speed of Help NEGATIEF schaadt berry-prestatie",""), IF(AND(O2="Ingredient Finding",S2="Ingredient"),"Let op: Ingredient Finding NEGATIEF schaadt ingredient-prestatie","") )) -> Evolve naar Raichu = snelste berry helper!; Perfecte nature voor Ingredient team!
A3: Squirtle | B3: 8 | C3: Water | D3: =IF(C3="","",VLOOKUP(C3,Referentie!$A$2:$B$19,2,0)) -> Oran | E3: Moomoo Milk | F3: Soothing Cacao | G3: Soothing Cacao | H3: Ingredient Finder S | I3: Skill Trigger S | J3: Inventory Up L | K3: Skill Trigger M | L3: Inventory Up S | M3: Serious | N3: =IF(M3="","",VLOOKUP(M3,Referentie!$G$2:$I$26,2,0)) -> Neutral | O3: =IF(M3="","",VLOOKUP(M3,Referentie!$G$2:$I$26,3,0)) -> Neutral | P3: =IF(A3="","", (IF(N3="Speed of Help",2,0)) + (IF(O3="Speed of Help",-2,0)) + (IF(N3="EXP Gains",1,0)) + (IF(O3="EXP Gains",-1,0)) + (COUNTIF(H3:L3,"Helping Speed S")*1) + (COUNTIF(H3:L3,"Helping Speed M")*2) + (COUNTIF(H3:L3,"Berry Finding S")*2) + (COUNTIF(H3:L3,"Helping Bonus")*1) + (IF(O3="Ingredient Finding",0,0)) + (IF(O3="Main Skill Chance",0,0)) ) -> 0 | Q3: =IF(A3="","", (IF(N3="Ingredient Finding",2,0)) + (IF(O3="Ingredient Finding",-2,0)) + (IF(N3="EXP Gains",1,0)) + (IF(O3="EXP Gains",-1,0)) + (COUNTIF(H3:L3,"Ingredient Finder S")*1) + (COUNTIF(H3:L3,"Ingredient Finder M")*2) + (COUNTIF(H3:L3,"Inventory Up S")*0.5) + (COUNTIF(H3:L3,"Inventory Up M")*1) + (COUNTIF(H3:L3,"Inventory Up L")*1.5) + (IF(E3=F3,1,0)) + (IF(F3=G3,1,0)) ) -> 4 | R3: =IF(A3="","", (IF(N3="Main Skill Chance",2,0)) + (IF(O3="Main Skill Chance",-2,0)) + (IF(N3="EXP Gains",1,0)) + (IF(O3="EXP Gains",-1,0)) + (COUNTIF(H3:L3,"Skill Trigger S")*1) + (COUNTIF(H3:L3,"Skill Trigger M")*2) + (COUNTIF(H3:L3,"Skill Level Up S")*1) + (COUNTIF(H3:L3,"Skill Level Up M")*2) + (COUNTIF(H3:L3,"Energy Recovery Bonus")*1.5) + (COUNTIF(H3:L3,"Sleep EXP Bonus")*1) + (COUNTIF(H3:L3,"Research EXP Bonus")*1) ) -> 3 | S3: =IF(A3="","", IF(AND(P3<=1, Q3<=1, R3<=1), "Bench", IF(AND(P3>=Q3, P3>=R3), "Berry", IF(AND(Q3>=P3, Q3>=R3), "Ingredient", "Skill"))) ) -> Ingredient | T3: =IF(A3="","", MAX(P3,Q3,R3) + IF(OR(N3="Speed of Help",N3="Ingredient Finding",N3="Main Skill Chance"),1,0) + IF(N3="Neutral",0, IF(O3="Neutral",0.5,0)) + IF(B3>=10,0.5,0) ) -> 4 | U3: =IF(A3="","", IF(T3>=7, "⭐ Keep", IF(T3>=5, "📈 Level Up", IF(T3>=3, "🤔 Bench", "❌ Transfer"))) ) -> 🤔 Bench | V3: =IF(A3="","", _xlfn.TEXTJOIN("; ",TRUE, IF(A3="Pikachu","Evolve naar Raichu = snelste berry helper!",""), IF(A3="Pichu","Evolve → Pikachu → Raichu (top berry)",""), IF(A3="Eevee","Sylveon (skill) of Jolteon (berry) = top evoluties",""), IF(A3="Igglybuff","Evolve → Wigglytuff = Energy for Everyone S (top skill!)",""), IF(A3="Squirtle","Kanto starter: 2x ingrediënten + Ingredient Magnet S",""), IF(A3="Charmander","Evolve → Charizard = snelle berry+ingredient verzamelaar",""), IF(A3="Bulbasaur","Kanto starter: 2x ingrediënten + Ingredient Magnet S",""), IF(A3="Growlithe","Evolve → Arcanine = sterke all-rounder",""), IF(A3="Mareep","Evolve → Ampharos = hoge frequentie + waardevolle ingrediënten",""), IF(A3="Spheal","Evolve → Walrein = key voor Snowdrop Tundra (berry+ingr)",""), IF(A3="Riolu","Evolve → Lucario = sterke fighter",""), IF(A3="Togepi","Let op: Togekiss Metronome is onbetrouwbaar",""), IF(A3="Totodile","Evolve → Feraligatr = top berry voor Cyan Beach",""), IF(A3="Magnemite","Evolve → Magnezone = sterke skill helper",""), IF(A3="Ivysaur","Evolve → Venusaur = 2x ingrediënten specialist",""), IF(OR(N3="Neutral",O3="Neutral"),"Neutrale nature = ok maar niet ideaal",""), IF(AND(N3="Speed of Help",OR(S3="Berry",S3="Ingredient")),"Perfecte nature voor "&S3&" team!",""), IF(AND(N3="Ingredient Finding",S3="Ingredient"),"Perfecte nature voor Ingredient team!",""), IF(AND(N3="Main Skill Chance",S3="Skill"),"Perfecte nature voor Skill team!",""), IF(AND(O3="Speed of Help",S3="Berry"),"Let op: Speed of Help NEGATIEF schaadt berry-prestatie",""), IF(AND(O3="Ingredient Finding",S3="Ingredient"),"Let op: Ingredient Finding NEGATIEF schaadt ingredient-prestatie","") )) -> Kanto starter: 2x ingrediënten + Ingredient Magnet S; Neutrale nature = ok maar niet ideaal
A4: Igglybuff | B4: 9 | C4: Fairy | D4: =IF(C4="","",VLOOKUP(C4,Referentie!$A$2:$B$19,2,0)) -> Pecha | E4: Honey | F4: Honey | G4: Pure Oil | H4: Helping Speed S | I4: Ingredient Finder M | J4: Skill Trigger S | K4: Ingredient Finder S | L4: Inventory Up S | M4: Naive | N4: =IF(M4="","",VLOOKUP(M4,Referentie!$G$2:$I$26,2,0)) -> EXP Gains | O4: =IF(M4="","",VLOOKUP(M4,Referentie!$G$2:$I$26,3,0)) -> Main Skill Chance | P4: =IF(A4="","", (IF(N4="Speed of Help",2,0)) + (IF(O4="Speed of Help",-2,0)) + (IF(N4="EXP Gains",1,0)) + (IF(O4="EXP Gains",-1,0)) + (COUNTIF(H4:L4,"Helping Speed S")*1) + (COUNTIF(H4:L4,"Helping Speed M")*2) + (COUNTIF(H4:L4,"Berry Finding S")*2) + (COUNTIF(H4:L4,"Helping Bonus")*1) + (IF(O4="Ingredient Finding",0,0)) + (IF(O4="Main Skill Chance",0,0)) ) -> 2 | Q4: =IF(A4="","", (IF(N4="Ingredient Finding",2,0)) + (IF(O4="Ingredient Finding",-2,0)) + (IF(N4="EXP Gains",1,0)) + (IF(O4="EXP Gains",-1,0)) + (COUNTIF(H4:L4,"Ingredient Finder S")*1) + (COUNTIF(H4:L4,"Ingredient Finder M")*2) + (COUNTIF(H4:L4,"Inventory Up S")*0.5) + (COUNTIF(H4:L4,"Inventory Up M")*1) + (COUNTIF(H4:L4,"Inventory Up L")*1.5) + (IF(E4=F4,1,0)) + (IF(F4=G4,1,0)) ) -> 5.5 | R4: =IF(A4="","", (IF(N4="Main Skill Chance",2,0)) + (IF(O4="Main Skill Chance",-2,0)) + (IF(N4="EXP Gains",1,0)) + (IF(O4="EXP Gains",-1,0)) + (COUNTIF(H4:L4,"Skill Trigger S")*1) + (COUNTIF(H4:L4,"Skill Trigger M")*2) + (COUNTIF(H4:L4,"Skill Level Up S")*1) + (COUNTIF(H4:L4,"Skill Level Up M")*2) + (COUNTIF(H4:L4,"Energy Recovery Bonus")*1.5) + (COUNTIF(H4:L4,"Sleep EXP Bonus")*1) + (COUNTIF(H4:L4,"Research EXP Bonus")*1) ) -> 0 | S4: =IF(A4="","", IF(AND(P4<=1, Q4<=1, R4<=1), "Bench", IF(AND(P4>=Q4, P4>=R4), "Berry", IF(AND(Q4>=P4, Q4>=R4), "Ingredient", "Skill"))) ) -> Ingredient | T4: =IF(A4="","", MAX(P4,Q4,R4) + IF(OR(N4="Speed of Help",N4="Ingredient Finding",N4="Main Skill Chance"),1,0) + IF(N4="Neutral",0, IF(O4="Neutral",0.5,0)) + IF(B4>=10,0.5,0) ) -> 5.5 | U4: =IF(A4="","", IF(T4>=7, "⭐ Keep", IF(T4>=5, "📈 Level Up", IF(T4>=3, "🤔 Bench", "❌ Transfer"))) ) -> 📈 Level Up | V4: =IF(A4="","", _xlfn.TEXTJOIN("; ",TRUE, IF(A4="Pikachu","Evolve naar Raichu = snelste berry helper!",""), IF(A4="Pichu","Evolve → Pikachu → Raichu (top berry)",""), IF(A4="Eevee","Sylveon (skill) of Jolteon (berry) = top evoluties",""), IF(A4="Igglybuff","Evolve → Wigglytuff = Energy for Everyone S (top skill!)",""), IF(A4="Squirtle","Kanto starter: 2x ingrediënten + Ingredient Magnet S",""), IF(A4="Charmander","Evolve → Charizard = snelle berry+ingredient verzamelaar",""), IF(A4="Bulbasaur","Kanto starter: 2x ingrediënten + Ingredient Magnet S",""), IF(A4="Growlithe","Evolve → Arcanine = sterke all-rounder",""), IF(A4="Mareep","Evolve → Ampharos = hoge frequentie + waardevolle ingrediënten",""), IF(A4="Spheal","Evolve → Walrein = key voor Snowdrop Tundra (berry+ingr)",""), IF(A4="Riolu","Evolve → Lucario = sterke fighter",""), IF(A4="Togepi","Let op: Togekiss Metronome is onbetrouwbaar",""), IF(A4="Totodile","Evolve → Feraligatr = top berry voor Cyan Beach",""), IF(A4="Magnemite","Evolve → Magnezone = sterke skill helper",""), IF(A4="Ivysaur","Evolve → Venusaur = 2x ingrediënten specialist",""), IF(OR(N4="Neutral",O4="Neutral"),"Neutrale nature = ok maar niet ideaal",""), IF(AND(N4="Speed of Help",OR(S4="Berry",S4="Ingredient")),"Perfecte nature voor "&S4&" team!",""), IF(AND(N4="Ingredient Finding",S4="Ingredient"),"Perfecte nature voor Ingredient team!",""), IF(AND(N4="Main Skill Chance",S4="Skill"),"Perfecte nature voor Skill team!",""), IF(AND(O4="Speed of Help",S4="Berry"),"Let op: Speed of Help NEGATIEF schaadt berry-prestatie",""), IF(AND(O4="Ingredient Finding",S4="Ingredient"),"Let op: Ingredient Finding NEGATIEF schaadt ingredient-prestatie","") )) -> Evolve → Wigglytuff = Energy for Everyone S (top skill!)
A5: Spheal | B5: 11 | C5: Water | D5: =IF(C5="","",VLOOKUP(C5,Referentie!$A$2:$B$19,2,0)) -> Oran | E5: Pure Oil | F5: Bean Sausage | G5: Pure Oil | H5: Ingredient Finder S | I5: Helping Speed S | J5: Berry Finding S | K5: Inventory Up S | L5: Ingredient Finder M | M5: Bold | N5: =IF(M5="","",VLOOKUP(M5,Referentie!$G$2:$I$26,2,0)) -> Energy Recovery | O5: =IF(M5="","",VLOOKUP(M5,Referentie!$G$2:$I$26,3,0)) -> Speed of Help | P5: =IF(A5="","", (IF(N5="Speed of Help",2,0)) + (IF(O5="Speed of Help",-2,0)) + (IF(N5="EXP Gains",1,0)) + (IF(O5="EXP Gains",-1,0)) + (COUNTIF(H5:L5,"Helping Speed S")*1) + (COUNTIF(H5:L5,"Helping Speed M")*2) + (COUNTIF(H5:L5,"Berry Finding S")*2) + (COUNTIF(H5:L5,"Helping Bonus")*1) + (IF(O5="Ingredient Finding",0,0)) + (IF(O5="Main Skill Chance",0,0)) ) -> 1 | Q5: =IF(A5="","", (IF(N5="Ingredient Finding",2,0)) + (IF(O5="Ingredient Finding",-2,0)) + (IF(N5="EXP Gains",1,0)) + (IF(O5="EXP Gains",-1,0)) + (COUNTIF(H5:L5,"Ingredient Finder S")*1) + (COUNTIF(H5:L5,"Ingredient Finder M")*2) + (COUNTIF(H5:L5,"Inventory Up S")*0.5) + (COUNTIF(H5:L5,"Inventory Up M")*1) + (COUNTIF(H5:L5,"Inventory Up L")*1.5) + (IF(E5=F5,1,0)) + (IF(F5=G5,1,0)) ) -> 3.5 | R5: =IF(A5="","", (IF(N5="Main Skill Chance",2,0)) + (IF(O5="Main Skill Chance",-2,0)) + (IF(N5="EXP Gains",1,0)) + (IF(O5="EXP Gains",-1,0)) + (COUNTIF(H5:L5,"Skill Trigger S")*1) + (COUNTIF(H5:L5,"Skill Trigger M")*2) + (COUNTIF(H5:L5,"Skill Level Up S")*1) + (COUNTIF(H5:L5,"Skill Level Up M")*2) + (COUNTIF(H5:L5,"Energy Recovery Bonus")*1.5) + (COUNTIF(H5:L5,"Sleep EXP Bonus")*1) + (COUNTIF(H5:L5,"Research EXP Bonus")*1) ) -> 0 | S5: =IF(A5="","", IF(AND(P5<=1, Q5<=1, R5<=1), "Bench", IF(AND(P5>=Q5, P5>=R5), "Berry", IF(AND(Q5>=P5, Q5>=R5), "Ingredient", "Skill"))) ) -> Ingredient | T5: =IF(A5="","", MAX(P5,Q5,R5) + IF(OR(N5="Speed of Help",N5="Ingredient Finding",N5="Main Skill Chance"),1,0) + IF(N5="Neutral",0, IF(O5="Neutral",0.5,0)) + IF(B5>=10,0.5,0) ) -> 4 | U5: =IF(A5="","", IF(T5>=7, "⭐ Keep", IF(T5>=5, "📈 Level Up", IF(T5>=3, "🤔 Bench", "❌ Transfer"))) ) -> 🤔 Bench | V5: =IF(A5="","", _xlfn.TEXTJOIN("; ",TRUE, IF(A5="Pikachu","Evolve naar Raichu = snelste berry helper!",""), IF(A5="Pichu","Evolve → Pikachu → Raichu (top berry)",""), IF(A5="Eevee","Sylveon (skill) of Jolteon (berry) = top evoluties",""), IF(A5="Igglybuff","Evolve → Wigglytuff = Energy for Everyone S (top skill!)",""), IF(A5="Squirtle","Kanto starter: 2x ingrediënten + Ingredient Magnet S",""), IF(A5="Charmander","Evolve → Charizard = snelle berry+ingredient verzamelaar",""), IF(A5="Bulbasaur","Kanto starter: 2x ingrediënten + Ingredient Magnet S",""), IF(A5="Growlithe","Evolve → Arcanine = sterke all-rounder",""), IF(A5="Mareep","Evolve → Ampharos = hoge frequentie + waardevolle ingrediënten",""), IF(A5="Spheal","Evolve → Walrein = key voor Snowdrop Tundra (berry+ingr)",""), IF(A5="Riolu","Evolve → Lucario = sterke fighter",""), IF(A5="Togepi","Let op: Togekiss Metronome is onbetrouwbaar",""), IF(A5="Totodile","Evolve → Feraligatr = top berry voor Cyan Beach",""), IF(A5="Magnemite","Evolve → Magnezone = sterke skill helper",""), IF(A5="Ivysaur","Evolve → Venusaur = 2x ingrediënten specialist",""), IF(OR(N5="Neutral",O5="Neutral"),"Neutrale nature = ok maar niet ideaal",""), IF(AND(N5="Speed of Help",OR(S5="Berry",S5="Ingredient")),"Perfecte nature voor "&S5&" team!",""), IF(AND(N5="Ingredient Finding",S5="Ingredient"),"Perfecte nature voor Ingredient team!",""), IF(AND(N5="Main Skill Chance",S5="Skill"),"Perfecte nature voor Skill team!",""), IF(AND(O5="Speed of Help",S5="Berry"),"Let op: Speed of Help NEGATIEF schaadt berry-prestatie",""), IF(AND(O5="Ingredient Finding",S5="Ingredient"),"Let op: Ingredient Finding NEGATIEF schaadt ingredient-prestatie","") )) -> Evolve → Walrein = key voor Snowdrop Tundra (berry+ingr)
A6: Cubone | B6: 11 | C6: Ground | D6: =IF(C6="","",VLOOKUP(C6,Referentie!$A$2:$B$19,2,0)) -> Figy | E6: Warming Ginger | F6: Soothing Cacao | G6: Warming Ginger | H6: Helping Speed M | I6: Ingredient Finder S | J6: Skill Trigger M | K6: Skill Level Up M | L6: Skill Trigger S | M6: Naughty | N6: =IF(M6="","",VLOOKUP(M6,Referentie!$G$2:$I$26,2,0)) -> Speed of Help | O6: =IF(M6="","",VLOOKUP(M6,Referentie!$G$2:$I$26,3,0)) -> Main Skill Chance | P6: =IF(A6="","", (IF(N6="Speed of Help",2,0)) + (IF(O6="Speed of Help",-2,0)) + (IF(N6="EXP Gains",1,0)) + (IF(O6="EXP Gains",-1,0)) + (COUNTIF(H6:L6,"Helping Speed S")*1) + (COUNTIF(H6:L6,"Helping Speed M")*2) + (COUNTIF(H6:L6,"Berry Finding S")*2) + (COUNTIF(H6:L6,"Helping Bonus")*1) + (IF(O6="Ingredient Finding",0,0)) + (IF(O6="Main Skill Chance",0,0)) ) -> 4 | Q6: =IF(A6="","", (IF(N6="Ingredient Finding",2,0)) + (IF(O6="Ingredient Finding",-2,0)) + (IF(N6="EXP Gains",1,0)) + (IF(O6="EXP Gains",-1,0)) + (COUNTIF(H6:L6,"Ingredient Finder S")*1) + (COUNTIF(H6:L6,"Ingredient Finder M")*2) + (COUNTIF(H6:L6,"Inventory Up S")*0.5) + (COUNTIF(H6:L6,"Inventory Up M")*1) + (COUNTIF(H6:L6,"Inventory Up L")*1.5) + (IF(E6=F6,1,0)) + (IF(F6=G6,1,0)) ) -> 1 | R6: =IF(A6="","", (IF(N6="Main Skill Chance",2,0)) + (IF(O6="Main Skill Chance",-2,0)) + (IF(N6="EXP Gains",1,0)) + (IF(O6="EXP Gains",-1,0)) + (COUNTIF(H6:L6,"Skill Trigger S")*1) + (COUNTIF(H6:L6,"Skill Trigger M")*2) + (COUNTIF(H6:L6,"Skill Level Up S")*1) + (COUNTIF(H6:L6,"Skill Level Up M")*2) + (COUNTIF(H6:L6,"Energy Recovery Bonus")*1.5) + (COUNTIF(H6:L6,"Sleep EXP Bonus")*1) + (COUNTIF(H6:L6,"Research EXP Bonus")*1) ) -> 3 | S6: =IF(A6="","", IF(AND(P6<=1, Q6<=1, R6<=1), "Bench", IF(AND(P6>=Q6, P6>=R6), "Berry", IF(AND(Q6>=P6, Q6>=R6), "Ingredient", "Skill"))) ) -> Berry | T6: =IF(A6="","", MAX(P6,Q6,R6) + IF(OR(N6="Speed of Help",N6="Ingredient Finding",N6="Main Skill Chance"),1,0) + IF(N6="Neutral",0, IF(O6="Neutral",0.5,0)) + IF(B6>=10,0.5,0) ) -> 5.5 | U6: =IF(A6="","", IF(T6>=7, "⭐ Keep", IF(T6>=5, "📈 Level Up", IF(T6>=3, "🤔 Bench", "❌ Transfer"))) ) -> 📈 Level Up | V6: =IF(A6="","", _xlfn.TEXTJOIN("; ",TRUE, IF(A6="Pikachu","Evolve naar Raichu = snelste berry helper!",""), IF(A6="Pichu","Evolve → Pikachu → Raichu (top berry)",""), IF(A6="Eevee","Sylveon (skill) of Jolteon (berry) = top evoluties",""), IF(A6="Igglybuff","Evolve → Wigglytuff = Energy for Everyone S (top skill!)",""), IF(A6="Squirtle","Kanto starter: 2x ingrediënten + Ingredient Magnet S",""), IF(A6="Charmander","Evolve → Charizard = snelle berry+ingredient verzamelaar",""), IF(A6="Bulbasaur","Kanto starter: 2x ingrediënten + Ingredient Magnet S",""), IF(A6="Growlithe","Evolve → Arcanine = sterke all-rounder",""), IF(A6="Mareep","Evolve → Ampharos = hoge frequentie + waardevolle ingrediënten",""), IF(A6="Spheal","Evolve → Walrein = key voor Snowdrop Tundra (berry+ingr)",""), IF(A6="Riolu","Evolve → Lucario = sterke fighter",""), IF(A6="Togepi","Let op: Togekiss Metronome is onbetrouwbaar",""), IF(A6="Totodile","Evolve → Feraligatr = top berry voor Cyan Beach",""), IF(A6="Magnemite","Evolve → Magnezone = sterke skill helper",""), IF(A6="Ivysaur","Evolve → Venusaur = 2x ingrediënten specialist",""), IF(OR(N6="Neutral",O6="Neutral"),"Neutrale nature = ok maar niet ideaal",""), IF(AND(N6="Speed of Help",OR(S6="Berry",S6="Ingredient")),"Perfecte nature voor "&S6&" team!",""), IF(AND(N6="Ingredient Finding",S6="Ingredient"),"Perfecte nature voor Ingredient team!",""), IF(AND(N6="Main Skill Chance",S6="Skill"),"Perfecte nature voor Skill team!",""), IF(AND(O6="Speed of Help",S6="Berry"),"Let op: Speed of Help NEGATIEF schaadt berry-prestatie",""), IF(AND(O6="Ingredient Finding",S6="Ingredient"),"Let op: Ingredient Finding NEGATIEF schaadt ingredient-prestatie","") )) -> Perfecte nature voor Berry team!
A7: Pichu | B7: 6 | C7: Electric | D7: =IF(C7="","",VLOOKUP(C7,Referentie!$A$2:$B$19,2,0)) -> Grepa | E7: Fancy Apple | F7: Warming Ginger | G7: Fancy Apple | H7: Inventory Up S | I7: Inventory Up L | J7: Ingredient Finder M | K7: Helping Speed M | L7: Skill Level Up S | M7: Impish | N7: =IF(M7="","",VLOOKUP(M7,Referentie!$G$2:$I$26,2,0)) -> Energy Recovery | O7: =IF(M7="","",VLOOKUP(M7,Referentie!$G$2:$I$26,3,0)) -> Ingredient Finding | P7: =IF(A7="","", (IF(N7="Speed of Help",2,0)) + (IF(O7="Speed of Help",-2,0)) + (IF(N7="EXP Gains",1,0)) + (IF(O7="EXP Gains",-1,0)) + (COUNTIF(H7:L7,"Helping Speed S")*1) + (COUNTIF(H7:L7,"Helping Speed M")*2) + (COUNTIF(H7:L7,"Berry Finding S")*2) + (COUNTIF(H7:L7,"Helping Bonus")*1) + (IF(O7="Ingredient Finding",0,0)) + (IF(O7="Main Skill Chance",0,0)) ) -> 2 | Q7: =IF(A7="","", (IF(N7="Ingredient Finding",2,0)) + (IF(O7="Ingredient Finding",-2,0)) + (IF(N7="EXP Gains",1,0)) + (IF(O7="EXP Gains",-1,0)) + (COUNTIF(H7:L7,"Ingredient Finder S")*1) + (COUNTIF(H7:L7,"Ingredient Finder M")*2) + (COUNTIF(H7:L7,"Inventory Up S")*0.5) + (COUNTIF(H7:L7,"Inventory Up M")*1) + (COUNTIF(H7:L7,"Inventory Up L")*1.5) + (IF(E7=F7,1,0)) + (IF(F7=G7,1,0)) ) -> 2 | R7: =IF(A7="","", (IF(N7="Main Skill Chance",2,0)) + (IF(O7="Main Skill Chance",-2,0)) + (IF(N7="EXP Gains",1,0)) + (IF(O7="EXP Gains",-1,0)) + (COUNTIF(H7:L7,"Skill Trigger S")*1) + (COUNTIF(H7:L7,"Skill Trigger M")*2) + (COUNTIF(H7:L7,"Skill Level Up S")*1) + (COUNTIF(H7:L7,"Skill Level Up M")*2) + (COUNTIF(H7:L7,"Energy Recovery Bonus")*1.5) + (COUNTIF(H7:L7,"Sleep EXP Bonus")*1) + (COUNTIF(H7:L7,"Research EXP Bonus")*1) ) -> 1 | S7: =IF(A7="","", IF(AND(P7<=1, Q7<=1, R7<=1), "Bench", IF(AND(P7>=Q7, P7>=R7), "Berry", IF(AND(Q7>=P7, Q7>=R7), "Ingredient", "Skill"))) ) -> Berry | T7: =IF(A7="","", MAX(P7,Q7,R7) + IF(OR(N7="Speed of Help",N7="Ingredient Finding",N7="Main Skill Chance"),1,0) + IF(N7="Neutral",0, IF(O7="Neutral",0.5,0)) + IF(B7>=10,0.5,0) ) -> 2 | U7: =IF(A7="","", IF(T7>=7, "⭐ Keep", IF(T7>=5, "📈 Level Up", IF(T7>=3, "🤔 Bench", "❌ Transfer"))) ) -> ❌ Transfer | V7: =IF(A7="","", _xlfn.TEXTJOIN("; ",TRUE, IF(A7="Pikachu","Evolve naar Raichu = snelste berry helper!",""), IF(A7="Pichu","Evolve → Pikachu → Raichu (top berry)",""), IF(A7="Eevee","Sylveon (skill) of Jolteon (berry) = top evoluties",""), IF(A7="Igglybuff","Evolve → Wigglytuff = Energy for Everyone S (top skill!)",""), IF(A7="Squirtle","Kanto starter: 2x ingrediënten + Ingredient Magnet S",""), IF(A7="Charmander","Evolve → Charizard = snelle berry+ingredient verzamelaar",""), IF(A7="Bulbasaur","Kanto starter: 2x ingrediënten + Ingredient Magnet S",""), IF(A7="Growlithe","Evolve → Arcanine = sterke all-rounder",""), IF(A7="Mareep","Evolve → Ampharos = hoge frequentie + waardevolle ingrediënten",""), IF(A7="Spheal","Evolve → Walrein = key voor Snowdrop Tundra (berry+ingr)",""), IF(A7="Riolu","Evolve → Lucario = sterke fighter",""), IF(A7="Togepi","Let op: Togekiss Metronome is onbetrouwbaar",""), IF(A7="Totodile","Evolve → Feraligatr = top berry voor Cyan Beach",""), IF(A7="Magnemite","Evolve → Magnezone = sterke skill helper",""), IF(A7="Ivysaur","Evolve → Venusaur = 2x ingrediënten specialist",""), IF(OR(N7="Neutral",O7="Neutral"),"Neutrale nature = ok maar niet ideaal",""), IF(AND(N7="Speed of Help",OR(S7="Berry",S7="Ingredient")),"Perfecte nature voor "&S7&" team!",""), IF(AND(N7="Ingredient Finding",S7="Ingredient"),"Perfecte nature voor Ingredient team!",""), IF(AND(N7="Main Skill Chance",S7="Skill"),"Perfecte nature voor Skill team!",""), IF(AND(O7="Speed of Help",S7="Berry"),"Let op: Speed of Help NEGATIEF schaadt berry-prestatie",""), IF(AND(O7="Ingredient Finding",S7="Ingredient"),"Let op: Ingredient Finding NEGATIEF schaadt ingredient-prestatie","") )) -> Evolve → Pikachu → Raichu (top berry)
A8: Slowpoke | B8: 9 | C8: Water | D8: =IF(C8="","",VLOOKUP(C8,Referentie!$A$2:$B$19,2,0)) -> Oran | E8: Soothing Cacao | F8: Slowpoke Tail | G8: Soothing Cacao | H8: Ingredient Finder S | I8: Helping Speed S | J8: Inventory Up S | K8: Skill Trigger S | L8: Inventory Up M | M8: Jolly | N8: =IF(M8="","",VLOOKUP(M8,Referentie!$G$2:$I$26,2,0)) -> EXP Gains | O8: =IF(M8="","",VLOOKUP(M8,Referentie!$G$2:$I$26,3,0)) -> Ingredient Finding | P8: =IF(A8="","", (IF(N8="Speed of Help",2,0)) + (IF(O8="Speed of Help",-2,0)) + (IF(N8="EXP Gains",1,0)) + (IF(O8="EXP Gains",-1,0)) + (COUNTIF(H8:L8,"Helping Speed S")*1) + (COUNTIF(H8:L8,"Helping Speed M")*2) + (COUNTIF(H8:L8,"Berry Finding S")*2) + (COUNTIF(H8:L8,"Helping Bonus")*1) + (IF(O8="Ingredient Finding",0,0)) + (IF(O8="Main Skill Chance",0,0)) ) -> 2 | Q8: =IF(A8="","", (IF(N8="Ingredient Finding",2,0)) + (IF(O8="Ingredient Finding",-2,0)) + (IF(N8="EXP Gains",1,0)) + (IF(O8="EXP Gains",-1,0)) + (COUNTIF(H8:L8,"Ingredient Finder S")*1) + (COUNTIF(H8:L8,"Ingredient Finder M")*2) + (COUNTIF(H8:L8,"Inventory Up S")*0.5) + (COUNTIF(H8:L8,"Inventory Up M")*1) + (COUNTIF(H8:L8,"Inventory Up L")*1.5) + (IF(E8=F8,1,0)) + (IF(F8=G8,1,0)) ) -> 1.5 | R8: =IF(A8="","", (IF(N8="Main Skill Chance",2,0)) + (IF(O8="Main Skill Chance",-2,0)) + (IF(N8="EXP Gains",1,0)) + (IF(O8="EXP Gains",-1,0)) + (COUNTIF(H8:L8,"Skill Trigger S")*1) + (COUNTIF(H8:L8,"Skill Trigger M")*2) + (COUNTIF(H8:L8,"Skill Level Up S")*1) + (COUNTIF(H8:L8,"Skill Level Up M")*2) + (COUNTIF(H8:L8,"Energy Recovery Bonus")*1.5) + (COUNTIF(H8:L8,"Sleep EXP Bonus")*1) + (COUNTIF(H8:L8,"Research EXP Bonus")*1) ) -> 2 | S8: =IF(A8="","", IF(AND(P8<=1, Q8<=1, R8<=1), "Bench", IF(AND(P8>=Q8, P8>=R8), "Berry", IF(AND(Q8>=P8, Q8>=R8), "Ingredient", "Skill"))) ) -> Berry | T8: =IF(A8="","", MAX(P8,Q8,R8) + IF(OR(N8="Speed of Help",N8="Ingredient Finding",N8="Main Skill Chance"),1,0) + IF(N8="Neutral",0, IF(O8="Neutral",0.5,0)) + IF(B8>=10,0.5,0) ) -> 2 | U8: =IF(A8="","", IF(T8>=7, "⭐ Keep", IF(T8>=5, "📈 Level Up", IF(T8>=3, "🤔 Bench", "❌ Transfer"))) ) -> ❌ Transfer | V8: =IF(A8="","", _xlfn.TEXTJOIN("; ",TRUE, IF(A8="Pikachu","Evolve naar Raichu = snelste berry helper!",""), IF(A8="Pichu","Evolve → Pikachu → Raichu (top berry)",""), IF(A8="Eevee","Sylveon (skill) of Jolteon (berry) = top evoluties",""), IF(A8="Igglybuff","Evolve → Wigglytuff = Energy for Everyone S (top skill!)",""), IF(A8="Squirtle","Kanto starter: 2x ingrediënten + Ingredient Magnet S",""), IF(A8="Charmander","Evolve → Charizard = snelle berry+ingredient verzamelaar",""), IF(A8="Bulbasaur","Kanto starter: 2x ingrediënten + Ingredient Magnet S",""), IF(A8="Growlithe","Evolve → Arcanine = sterke all-rounder",""), IF(A8="Mareep","Evolve → Ampharos = hoge frequentie + waardevolle ingrediënten",""), IF(A8="Spheal","Evolve → Walrein = key voor Snowdrop Tundra (berry+ingr)",""), IF(A8="Riolu","Evolve → Lucario = sterke fighter",""), IF(A8="Togepi","Let op: Togekiss Metronome is onbetrouwbaar",""), IF(A8="Totodile","Evolve → Feraligatr = top berry voor Cyan Beach",""), IF(A8="Magnemite","Evolve → Magnezone = sterke skill helper",""), IF(A8="Ivysaur","Evolve → Venusaur = 2x ingrediënten specialist",""), IF(OR(N8="Neutral",O8="Neutral"),"Neutrale nature = ok maar niet ideaal",""), IF(AND(N8="Speed of Help",OR(S8="Berry",S8="Ingredient")),"Perfecte nature voor "&S8&" team!",""), IF(AND(N8="Ingredient Finding",S8="Ingredient"),"Perfecte nature voor Ingredient team!",""), IF(AND(N8="Main Skill Chance",S8="Skill"),"Perfecte nature voor Skill team!",""), IF(AND(O8="Speed of Help",S8="Berry"),"Let op: Speed of Help NEGATIEF schaadt berry-prestatie",""), IF(AND(O8="Ingredient Finding",S8="Ingredient"),"Let op: Ingredient Finding NEGATIEF schaadt ingredient-prestatie","") ))
A9: Noibat | B9: 14 | C9: Dragon | D9: =IF(C9="","",VLOOKUP(C9,Referentie!$A$2:$B$19,2,0)) -> Yache | E9: Fancy Apple | F9: Large Leek | G9: Bean Sausage | H9: Inventory Up S | I9: Inventory Up M | J9: Ingredient Finder M | K9: Skill Trigger S | L9: Ingredient Finder S | M9: Bashful | N9: =IF(M9="","",VLOOKUP(M9,Referentie!$G$2:$I$26,2,0)) -> Neutral | O9: =IF(M9="","",VLOOKUP(M9,Referentie!$G$2:$I$26,3,0)) -> Neutral | P9: =IF(A9="","", (IF(N9="Speed of Help",2,0)) + (IF(O9="Speed of Help",-2,0)) + (IF(N9="EXP Gains",1,0)) + (IF(O9="EXP Gains",-1,0)) + (COUNTIF(H9:L9,"Helping Speed S")*1) + (COUNTIF(H9:L9,"Helping Speed M")*2) + (COUNTIF(H9:L9,"Berry Finding S")*2) + (COUNTIF(H9:L9,"Helping Bonus")*1) + (IF(O9="Ingredient Finding",0,0)) + (IF(O9="Main Skill Chance",0,0)) ) -> 0 | Q9: =IF(A9="","", (IF(N9="Ingredient Finding",2,0)) + (IF(O9="Ingredient Finding",-2,0)) + (IF(N9="EXP Gains",1,0)) + (IF(O9="EXP Gains",-1,0)) + (COUNTIF(H9:L9,"Ingredient Finder S")*1) + (COUNTIF(H9:L9,"Ingredient Finder M")*2) + (COUNTIF(H9:L9,"Inventory Up S")*0.5) + (COUNTIF(H9:L9,"Inventory Up M")*1) + (COUNTIF(H9:L9,"Inventory Up L")*1.5) + (IF(E9=F9,1,0)) + (IF(F9=G9,1,0)) ) -> 4.5 | R9: =IF(A9="","", (IF(N9="Main Skill Chance",2,0)) + (IF(O9="Main Skill Chance",-2,0)) + (IF(N9="EXP Gains",1,0)) + (IF(O9="EXP Gains",-1,0)) + (COUNTIF(H9:L9,"Skill Trigger S")*1) + (COUNTIF(H9:L9,"Skill Trigger M")*2) + (COUNTIF(H9:L9,"Skill Level Up S")*1) + (COUNTIF(H9:L9,"Skill Level Up M")*2) + (COUNTIF(H9:L9,"Energy Recovery Bonus")*1.5) + (COUNTIF(H9:L9,"Sleep EXP Bonus")*1) + (COUNTIF(H9:L9,"Research EXP Bonus")*1) ) -> 1 | S9: =IF(A9="","", IF(AND(P9<=1, Q9<=1, R9<=1), "Bench", IF(AND(P9>=Q9, P9>=R9), "Berry", IF(AND(Q9>=P9, Q9>=R9), "Ingredient", "Skill"))) ) -> Ingredient | T9: =IF(A9="","", MAX(P9,Q9,R9) + IF(OR(N9="Speed of Help",N9="Ingredient Finding",N9="Main Skill Chance"),1,0) + IF(N9="Neutral",0, IF(O9="Neutral",0.5,0)) + IF(B9>=10,0.5,0) ) -> 5 | U9: =IF(A9="","", IF(T9>=7, "⭐ Keep", IF(T9>=5, "📈 Level Up", IF(T9>=3, "🤔 Bench", "❌ Transfer"))) ) -> 📈 Level Up | V9: =IF(A9="","", _xlfn.TEXTJOIN("; ",TRUE, IF(A9="Pikachu","Evolve naar Raichu = snelste berry helper!",""), IF(A9="Pichu","Evolve → Pikachu → Raichu (top berry)",""), IF(A9="Eevee","Sylveon (skill) of Jolteon (berry) = top evoluties",""), IF(A9="Igglybuff","Evolve → Wigglytuff = Energy for Everyone S (top skill!)",""), IF(A9="Squirtle","Kanto starter: 2x ingrediënten + Ingredient Magnet S",""), IF(A9="Charmander","Evolve → Charizard = snelle berry+ingredient verzamelaar",""), IF(A9="Bulbasaur","Kanto starter: 2x ingrediënten + Ingredient Magnet S",""), IF(A9="Growlithe","Evolve → Arcanine = sterke all-rounder",""), IF(A9="Mareep","Evolve → Ampharos = hoge frequentie + waardevolle ingrediënten",""), IF(A9="Spheal","Evolve → Walrein = key voor Snowdrop Tundra (berry+ingr)",""), IF(A9="Riolu","Evolve → Lucario = sterke fighter",""), IF(A9="Togepi","Let op: Togekiss Metronome is onbetrouwbaar",""), IF(A9="Totodile","Evolve → Feraligatr = top berry voor Cyan Beach",""), IF(A9="Magnemite","Evolve → Magnezone = sterke skill helper",""), IF(A9="Ivysaur","Evolve → Venusaur = 2x ingrediënten specialist",""), IF(OR(N9="Neutral",O9="Neutral"),"Neutrale nature = ok maar niet ideaal",""), IF(AND(N9="Speed of Help",OR(S9="Berry",S9="Ingredient")),"Perfecte nature voor "&S9&" team!",""), IF(AND(N9="Ingredient Finding",S9="Ingredient"),"Perfecte nature voor Ingredient team!",""), IF(AND(N9="Main Skill Chance",S9="Skill"),"Perfecte nature voor Skill team!",""), IF(AND(O9="Speed of Help",S9="Berry"),"Let op: Speed of Help NEGATIEF schaadt berry-prestatie",""), IF(AND(O9="Ingredient Finding",S9="Ingredient"),"Let op: Ingredient Finding NEGATIEF schaadt ingredient-prestatie","") )) -> Neutrale nature = ok maar niet ideaal
A10: Rattata | B10: 8 | C10: Normal | D10: =IF(C10="","",VLOOKUP(C10,Referentie!$A$2:$B$19,2,0)) -> Persim | E10: Fancy Apple | F10: Greengrass Soybeans | G10: Fancy Apple | H10: Helping Speed S | I10: Ingredient Finder M | J10: Research EXP Bonus | K10: Sleep EXP Bonus | L10: Ingredient Finder S | M10: Mild | N10: =IF(M10="","",VLOOKUP(M10,Referentie!$G$2:$I$26,2,0)) -> Ingredient Finding | O10: =IF(M10="","",VLOOKUP(M10,Referentie!$G$2:$I$26,3,0)) -> Energy Recovery | P10: =IF(A10="","", (IF(N10="Speed of Help",2,0)) + (IF(O10="Speed of Help",-2,0)) + (IF(N10="EXP Gains",1,0)) + (IF(O10="EXP Gains",-1,0)) + (COUNTIF(H10:L10,"Helping Speed S")*1) + (COUNTIF(H10:L10,"Helping Speed M")*2) + (COUNTIF(H10:L10,"Berry Finding S")*2) + (COUNTIF(H10:L10,"Helping Bonus")*1) + (IF(O10="Ingredient Finding",0,0)) + (IF(O10="Main Skill Chance",0,0)) ) -> 1 | Q10: =IF(A10="","", (IF(N10="Ingredient Finding",2,0)) + (IF(O10="Ingredient Finding",-2,0)) + (IF(N10="EXP Gains",1,0)) + (IF(O10="EXP Gains",-1,0)) + (COUNTIF(H10:L10,"Ingredient Finder S")*1) + (COUNTIF(H10:L10,"Ingredient Finder M")*2) + (COUNTIF(H10:L10,"Inventory Up S")*0.5) + (COUNTIF(H10:L10,"Inventory Up M")*1) + (COUNTIF(H10:L10,"Inventory Up L")*1.5) + (IF(E10=F10,1,0)) + (IF(F10=G10,1,0)) ) -> 5 | R10: =IF(A10="","", (IF(N10="Main Skill Chance",2,0)) + (IF(O10="Main Skill Chance",-2,0)) + (IF(N10="EXP Gains",1,0)) + (IF(O10="EXP Gains",-1,0)) + (COUNTIF(H10:L10,"Skill Trigger S")*1) + (COUNTIF(H10:L10,"Skill Trigger M")*2) + (COUNTIF(H10:L10,"Skill Level Up S")*1) + (COUNTIF(H10:L10,"Skill Level Up M")*2) + (COUNTIF(H10:L10,"Energy Recovery Bonus")*1.5) + (COUNTIF(H10:L10,"Sleep EXP Bonus")*1) + (COUNTIF(H10:L10,"Research EXP Bonus")*1) ) -> 2 | S10: =IF(A10="","", IF(AND(P10<=1, Q10<=1, R10<=1), "Bench", IF(AND(P10>=Q10, P10>=R10), "Berry", IF(AND(Q10>=P10, Q10>=R10), "Ingredient", "Skill"))) ) -> Ingredient | T10: =IF(A10="","", MAX(P10,Q10,R10) + IF(OR(N10="Speed of Help",N10="Ingredient Finding",N10="Main Skill Chance"),1,0) + IF(N10="Neutral",0, IF(O10="Neutral",0.5,0)) + IF(B10>=10,0.5,0) ) -> 6 | U10: =IF(A10="","", IF(T10>=7, "⭐ Keep", IF(T10>=5, "📈 Level Up", IF(T10>=3, "🤔 Bench", "❌ Transfer"))) ) -> 📈 Level Up | V10: =IF(A10="","", _xlfn.TEXTJOIN("; ",TRUE, IF(A10="Pikachu","Evolve naar Raichu = snelste berry helper!",""), IF(A10="Pichu","Evolve → Pikachu → Raichu (top berry)",""), IF(A10="Eevee","Sylveon (skill) of Jolteon (berry) = top evoluties",""), IF(A10="Igglybuff","Evolve → Wigglytuff = Energy for Everyone S (top skill!)",""), IF(A10="Squirtle","Kanto starter: 2x ingrediënten + Ingredient Magnet S",""), IF(A10="Charmander","Evolve → Charizard = snelle berry+ingredient verzamelaar",""), IF(A10="Bulbasaur","Kanto starter: 2x ingrediënten + Ingredient Magnet S",""), IF(A10="Growlithe","Evolve → Arcanine = sterke all-rounder",""), IF(A10="Mareep","Evolve → Ampharos = hoge frequentie + waardevolle ingrediënten",""), IF(A10="Spheal","Evolve → Walrein = key voor Snowdrop Tundra (berry+ingr)",""), IF(A10="Riolu","Evolve → Lucario = sterke fighter",""), IF(A10="Togepi","Let op: Togekiss Metronome is onbetrouwbaar",""), IF(A10="Totodile","Evolve → Feraligatr = top berry voor Cyan Beach",""), IF(A10="Magnemite","Evolve → Magnezone = sterke skill helper",""), IF(A10="Ivysaur","Evolve → Venusaur = 2x ingrediënten specialist",""), IF(OR(N10="Neutral",O10="Neutral"),"Neutrale nature = ok maar niet ideaal",""), IF(AND(N10="Speed of Help",OR(S10="Berry",S10="Ingredient")),"Perfecte nature voor "&S10&" team!",""), IF(AND(N10="Ingredient Finding",S10="Ingredient"),"Perfecte nature voor Ingredient team!",""), IF(AND(N10="Main Skill Chance",S10="Skill"),"Perfecte nature voor Skill team!",""), IF(AND(O10="Speed of Help",S10="Berry"),"Let op: Speed of Help NEGATIEF schaadt berry-prestatie",""), IF(AND(O10="Ingredient Finding",S10="Ingredient"),"Let op: Ingredient Finding NEGATIEF schaadt ingredient-prestatie","") )) -> Perfecte nature voor Ingredient team!
A11: Gulpin | B11: 9 | C11: Poison | D11: =IF(C11="","",VLOOKUP(C11,Referentie!$A$2:$B$19,2,0)) -> Chesto | E11: Greengrass Soybeans | F11: Greengrass Soybeans | G11: Tasty Mushroom | H11: Ingredient Finder M | I11: Ingredient Finder S | J11: Inventory Up S | K11: Helping Speed S | L11: Dream Shard Bonus | M11: Hasty | N11: =IF(M11="","",VLOOKUP(M11,Referentie!$G$2:$I$26,2,0)) -> EXP Gains | O11: =IF(M11="","",VLOOKUP(M11,Referentie!$G$2:$I$26,3,0)) -> Energy Recovery | P11: =IF(A11="","", (IF(N11="Speed of Help",2,0)) + (IF(O11="Speed of Help",-2,0)) + (IF(N11="EXP Gains",1,0)) + (IF(O11="EXP Gains",-1,0)) + (COUNTIF(H11:L11,"Helping Speed S")*1) + (COUNTIF(H11:L11,"Helping Speed M")*2) + (COUNTIF(H11:L11,"Berry Finding S")*2) + (COUNTIF(H11:L11,"Helping Bonus")*1) + (IF(O11="Ingredient Finding",0,0)) + (IF(O11="Main Skill Chance",0,0)) ) -> 2 | Q11: =IF(A11="","", (IF(N11="Ingredient Finding",2,0)) + (IF(O11="Ingredient Finding",-2,0)) + (IF(N11="EXP Gains",1,0)) + (IF(O11="EXP Gains",-1,0)) + (COUNTIF(H11:L11,"Ingredient Finder S")*1) + (COUNTIF(H11:L11,"Ingredient Finder M")*2) + (COUNTIF(H11:L11,"Inventory Up S")*0.5) + (COUNTIF(H11:L11,"Inventory Up M")*1) + (COUNTIF(H11:L11,"Inventory Up L")*1.5) + (IF(E11=F11,1,0)) + (IF(F11=G11,1,0)) ) -> 5.5 | R11: =IF(A11="","", (IF(N11="Main Skill Chance",2,0)) + (IF(O11="Main Skill Chance",-2,0)) + (IF(N11="EXP Gains",1,0)) + (IF(O11="EXP Gains",-1,0)) + (COUNTIF(H11:L11,"Skill Trigger S")*1) + (COUNTIF(H11:L11,"Skill Trigger M")*2) + (COUNTIF(H11:L11,"Skill Level Up S")*1) + (COUNTIF(H11:L11,"Skill Level Up M")*2) + (COUNTIF(H11:L11,"Energy Recovery Bonus")*1.5) + (COUNTIF(H11:L11,"Sleep EXP Bonus")*1) + (COUNTIF(H11:L11,"Research EXP Bonus")*1) ) -> 1 | S11: =IF(A11="","", IF(AND(P11<=1, Q11<=1, R11<=1), "Bench", IF(AND(P11>=Q11, P11>=R11), "Berry", IF(AND(Q11>=P11, Q11>=R11), "Ingredient", "Skill"))) ) -> Ingredient | T11: =IF(A11="","", MAX(P11,Q11,R11) + IF(OR(N11="Speed of Help",N11="Ingredient Finding",N11="Main Skill Chance"),1,0) + IF(N11="Neutral",0, IF(O11="Neutral",0.5,0)) + IF(B11>=10,0.5,0) ) -> 5.5 | U11: =IF(A11="","", IF(T11>=7, "⭐ Keep", IF(T11>=5, "📈 Level Up", IF(T11>=3, "🤔 Bench", "❌ Transfer"))) ) -> 📈 Level Up | V11: =IF(A11="","", _xlfn.TEXTJOIN("; ",TRUE, IF(A11="Pikachu","Evolve naar Raichu = snelste berry helper!",""), IF(A11="Pichu","Evolve → Pikachu → Raichu (top berry)",""), IF(A11="Eevee","Sylveon (skill) of Jolteon (berry) = top evoluties",""), IF(A11="Igglybuff","Evolve → Wigglytuff = Energy for Everyone S (top skill!)",""), IF(A11="Squirtle","Kanto starter: 2x ingrediënten + Ingredient Magnet S",""), IF(A11="Charmander","Evolve → Charizard = snelle berry+ingredient verzamelaar",""), IF(A11="Bulbasaur","Kanto starter: 2x ingrediënten + Ingredient Magnet S",""), IF(A11="Growlithe","Evolve → Arcanine = sterke all-rounder",""), IF(A11="Mareep","Evolve → Ampharos = hoge frequentie + waardevolle ingrediënten",""), IF(A11="Spheal","Evolve → Walrein = key voor Snowdrop Tundra (berry+ingr)",""), IF(A11="Riolu","Evolve → Lucario = sterke fighter",""), IF(A11="Togepi","Let op: Togekiss Metronome is onbetrouwbaar",""), IF(A11="Totodile","Evolve → Feraligatr = top berry voor Cyan Beach",""), IF(A11="Magnemite","Evolve → Magnezone = sterke skill helper",""), IF(A11="Ivysaur","Evolve → Venusaur = 2x ingrediënten specialist",""), IF(OR(N11="Neutral",O11="Neutral"),"Neutrale nature = ok maar niet ideaal",""), IF(AND(N11="Speed of Help",OR(S11="Berry",S11="Ingredient")),"Perfecte nature voor "&S11&" team!",""), IF(AND(N11="Ingredient Finding",S11="Ingredient"),"Perfecte nature voor Ingredient team!",""), IF(AND(N11="Main Skill Chance",S11="Skill"),"Perfecte nature voor Skill team!",""), IF(AND(O11="Speed of Help",S11="Berry"),"Let op: Speed of Help NEGATIEF schaadt berry-prestatie",""), IF(AND(O11="Ingredient Finding",S11="Ingredient"),"Let op: Ingredient Finding NEGATIEF schaadt ingredient-prestatie","") ))
A12: Swablu | B12: 7 | C12: Flying | D12: =IF(C12="","",VLOOKUP(C12,Referentie!$A$2:$B$19,2,0)) -> Lum | E12: Fancy Egg | F12: Greengrass Soybeans | G12: Fancy Egg | H12: Skill Trigger S | I12: Inventory Up S | J12: Helping Speed S | K12: Ingredient Finder S | L12: Berry Finding S | M12: Serious | N12: =IF(M12="","",VLOOKUP(M12,Referentie!$G$2:$I$26,2,0)) -> Neutral | O12: =IF(M12="","",VLOOKUP(M12,Referentie!$G$2:$I$26,3,0)) -> Neutral | P12: =IF(A12="","", (IF(N12="Speed of Help",2,0)) + (IF(O12="Speed of Help",-2,0)) + (IF(N12="EXP Gains",1,0)) + (IF(O12="EXP Gains",-1,0)) + (COUNTIF(H12:L12,"Helping Speed S")*1) + (COUNTIF(H12:L12,"Helping Speed M")*2) + (COUNTIF(H12:L12,"Berry Finding S")*2) + (COUNTIF(H12:L12,"Helping Bonus")*1) + (IF(O12="Ingredient Finding",0,0)) + (IF(O12="Main Skill Chance",0,0)) ) -> 3 | Q12: =IF(A12="","", (IF(N12="Ingredient Finding",2,0)) + (IF(O12="Ingredient Finding",-2,0)) + (IF(N12="EXP Gains",1,0)) + (IF(O12="EXP Gains",-1,0)) + (COUNTIF(H12:L12,"Ingredient Finder S")*1) + (COUNTIF(H12:L12,"Ingredient Finder M")*2) + (COUNTIF(H12:L12,"Inventory Up S")*0.5) + (COUNTIF(H12:L12,"Inventory Up M")*1) + (COUNTIF(H12:L12,"Inventory Up L")*1.5) + (IF(E12=F12,1,0)) + (IF(F12=G12,1,0)) ) -> 1.5 | R12: =IF(A12="","", (IF(N12="Main Skill Chance",2,0)) + (IF(O12="Main Skill Chance",-2,0)) + (IF(N12="EXP Gains",1,0)) + (IF(O12="EXP Gains",-1,0)) + (COUNTIF(H12:L12,"Skill Trigger S")*1) + (COUNTIF(H12:L12,"Skill Trigger M")*2) + (COUNTIF(H12:L12,"Skill Level Up S")*1) + (COUNTIF(H12:L12,"Skill Level Up M")*2) + (COUNTIF(H12:L12,"Energy Recovery Bonus")*1.5) + (COUNTIF(H12:L12,"Sleep EXP Bonus")*1) + (COUNTIF(H12:L12,"Research EXP Bonus")*1) ) -> 1 | S12: =IF(A12="","", IF(AND(P12<=1, Q12<=1, R12<=1), "Bench", IF(AND(P12>=Q12, P12>=R12), "Berry", IF(AND(Q12>=P12, Q12>=R12), "Ingredient", "Skill"))) ) -> Berry | T12: =IF(A12="","", MAX(P12,Q12,R12) + IF(OR(N12="Speed of Help",N12="Ingredient Finding",N12="Main Skill Chance"),1,0) + IF(N12="Neutral",0, IF(O12="Neutral",0.5,0)) + IF(B12>=10,0.5,0) ) -> 3 | U12: =IF(A12="","", IF(T12>=7, "⭐ Keep", IF(T12>=5, "📈 Level Up", IF(T12>=3, "🤔 Bench", "❌ Transfer"))) ) -> 🤔 Bench | V12: =IF(A12="","", _xlfn.TEXTJOIN("; ",TRUE, IF(A12="Pikachu","Evolve naar Raichu = snelste berry helper!",""), IF(A12="Pichu","Evolve → Pikachu → Raichu (top berry)",""), IF(A12="Eevee","Sylveon (skill) of Jolteon (berry) = top evoluties",""), IF(A12="Igglybuff","Evolve → Wigglytuff = Energy for Everyone S (top skill!)",""), IF(A12="Squirtle","Kanto starter: 2x ingrediënten + Ingredient Magnet S",""), IF(A12="Charmander","Evolve → Charizard = snelle berry+ingredient verzamelaar",""), IF(A12="Bulbasaur","Kanto starter: 2x ingrediënten + Ingredient Magnet S",""), IF(A12="Growlithe","Evolve → Arcanine = sterke all-rounder",""), IF(A12="Mareep","Evolve → Ampharos = hoge frequentie + waardevolle ingrediënten",""), IF(A12="Spheal","Evolve → Walrein = key voor Snowdrop Tundra (berry+ingr)",""), IF(A12="Riolu","Evolve → Lucario = sterke fighter",""), IF(A12="Togepi","Let op: Togekiss Metronome is onbetrouwbaar",""), IF(A12="Totodile","Evolve → Feraligatr = top berry voor Cyan Beach",""), IF(A12="Magnemite","Evolve → Magnezone = sterke skill helper",""), IF(A12="Ivysaur","Evolve → Venusaur = 2x ingrediënten specialist",""), IF(OR(N12="Neutral",O12="Neutral"),"Neutrale nature = ok maar niet ideaal",""), IF(AND(N12="Speed of Help",OR(S12="Berry",S12="Ingredient")),"Perfecte nature voor "&S12&" team!",""), IF(AND(N12="Ingredient Finding",S12="Ingredient"),"Perfecte nature voor Ingredient team!",""), IF(AND(N12="Main Skill Chance",S12="Skill"),"Perfecte nature voor Skill team!",""), IF(AND(O12="Speed of Help",S12="Berry"),"Let op: Speed of Help NEGATIEF schaadt berry-prestatie",""), IF(AND(O12="Ingredient Finding",S12="Ingredient"),"Let op: Ingredient Finding NEGATIEF schaadt ingredient-prestatie","") )) -> Neutrale nature = ok maar niet ideaal
A13: Igglybuff | B13: 4 | C13: Fairy | D13: =IF(C13="","",VLOOKUP(C13,Referentie!$A$2:$B$19,2,0)) -> Pecha | E13: Honey | F13: Pure Oil | G13: Honey | H13: Ingredient Finder M | I13: Skill Level Up S | J13: Skill Trigger S | K13: Inventory Up S | L13: Skill Level Up M | M13: Rash | N13: =IF(M13="","",VLOOKUP(M13,Referentie!$G$2:$I$26,2,0)) -> Ingredient Finding | O13: =IF(M13="","",VLOOKUP(M13,Referentie!$G$2:$I$26,3,0)) -> Main Skill Chance | P13: =IF(A13="","", (IF(N13="Speed of Help",2,0)) + (IF(O13="Speed of Help",-2,0)) + (IF(N13="EXP Gains",1,0)) + (IF(O13="EXP Gains",-1,0)) + (COUNTIF(H13:L13,"Helping Speed S")*1) + (COUNTIF(H13:L13,"Helping Speed M")*2) + (COUNTIF(H13:L13,"Berry Finding S")*2) + (COUNTIF(H13:L13,"Helping Bonus")*1) + (IF(O13="Ingredient Finding",0,0)) + (IF(O13="Main Skill Chance",0,0)) ) -> 0 | Q13: =IF(A13="","", (IF(N13="Ingredient Finding",2,0)) + (IF(O13="Ingredient Finding",-2,0)) + (IF(N13="EXP Gains",1,0)) + (IF(O13="EXP Gains",-1,0)) + (COUNTIF(H13:L13,"Ingredient Finder S")*1) + (COUNTIF(H13:L13,"Ingredient Finder M")*2) + (COUNTIF(H13:L13,"Inventory Up S")*0.5) + (COUNTIF(H13:L13,"Inventory Up M")*1) + (COUNTIF(H13:L13,"Inventory Up L")*1.5) + (IF(E13=F13,1,0)) + (IF(F13=G13,1,0)) ) -> 4.5 | R13: =IF(A13="","", (IF(N13="Main Skill Chance",2,0)) + (IF(O13="Main Skill Chance",-2,0)) + (IF(N13="EXP Gains",1,0)) + (IF(O13="EXP Gains",-1,0)) + (COUNTIF(H13:L13,"Skill Trigger S")*1) + (COUNTIF(H13:L13,"Skill Trigger M")*2) + (COUNTIF(H13:L13,"Skill Level Up S")*1) + (COUNTIF(H13:L13,"Skill Level Up M")*2) + (COUNTIF(H13:L13,"Energy Recovery Bonus")*1.5) + (COUNTIF(H13:L13,"Sleep EXP Bonus")*1) + (COUNTIF(H13:L13,"Research EXP Bonus")*1) ) -> 2 | S13: =IF(A13="","", IF(AND(P13<=1, Q13<=1, R13<=1), "Bench", IF(AND(P13>=Q13, P13>=R13), "Berry", IF(AND(Q13>=P13, Q13>=R13), "Ingredient", "Skill"))) ) -> Ingredient | T13: =IF(A13="","", MAX(P13,Q13,R13) + IF(OR(N13="Speed of Help",N13="Ingredient Finding",N13="Main Skill Chance"),1,0) + IF(N13="Neutral",0, IF(O13="Neutral",0.5,0)) + IF(B13>=10,0.5,0) ) -> 5.5 | U13: =IF(A13="","", IF(T13>=7, "⭐ Keep", IF(T13>=5, "📈 Level Up", IF(T13>=3, "🤔 Bench", "❌ Transfer"))) ) -> 📈 Level Up | V13: =IF(A13="","", _xlfn.TEXTJOIN("; ",TRUE, IF(A13="Pikachu","Evolve naar Raichu = snelste berry helper!",""), IF(A13="Pichu","Evolve → Pikachu → Raichu (top berry)",""), IF(A13="Eevee","Sylveon (skill) of Jolteon (berry) = top evoluties",""), IF(A13="Igglybuff","Evolve → Wigglytuff = Energy for Everyone S (top skill!)",""), IF(A13="Squirtle","Kanto starter: 2x ingrediënten + Ingredient Magnet S",""), IF(A13="Charmander","Evolve → Charizard = snelle berry+ingredient verzamelaar",""), IF(A13="Bulbasaur","Kanto starter: 2x ingrediënten + Ingredient Magnet S",""), IF(A13="Growlithe","Evolve → Arcanine = sterke all-rounder",""), IF(A13="Mareep","Evolve → Ampharos = hoge frequentie + waardevolle ingrediënten",""), IF(A13="Spheal","Evolve → Walrein = key voor Snowdrop Tundra (berry+ingr)",""), IF(A13="Riolu","Evolve → Lucario = sterke fighter",""), IF(A13="Togepi","Let op: Togekiss Metronome is onbetrouwbaar",""), IF(A13="Totodile","Evolve → Feraligatr = top berry voor Cyan Beach",""), IF(A13="Magnemite","Evolve → Magnezone = sterke skill helper",""), IF(A13="Ivysaur","Evolve → Venusaur = 2x ingrediënten specialist",""), IF(OR(N13="Neutral",O13="Neutral"),"Neutrale nature = ok maar niet ideaal",""), IF(AND(N13="Speed of Help",OR(S13="Berry",S13="Ingredient")),"Perfecte nature voor "&S13&" team!",""), IF(AND(N13="Ingredient Finding",S13="Ingredient"),"Perfecte nature voor Ingredient team!",""), IF(AND(N13="Main Skill Chance",S13="Skill"),"Perfecte nature voor Skill team!",""), IF(AND(O13="Speed of Help",S13="Berry"),"Let op: Speed of Help NEGATIEF schaadt berry-prestatie",""), IF(AND(O13="Ingredient Finding",S13="Ingredient"),"Let op: Ingredient Finding NEGATIEF schaadt ingredient-prestatie","") )) -> Evolve → Wigglytuff = Energy for Everyone S (top skill!); Perfecte nature voor Ingredient team!
... A55: Wynaut | B55: 8 | C55: Psychic | D55: =IF(C55="","",VLOOKUP(C55,Referentie!$A$2:$B$19,2,0)) -> Mago | E55: Fancy Apple | F55: Tasty Mushroom | G55: Pure Oil | H55: Inventory Up L | I55: Berry Finding S | J55: Inventory Up S | K55: Ingredient Finder S | L55: Skill Trigger S | M55: Sassy | N55: =IF(M55="","",VLOOKUP(M55,Referentie!$G$2:$I$26,2,0)) -> Main Skill Chance | O55: =IF(M55="","",VLOOKUP(M55,Referentie!$G$2:$I$26,3,0)) -> EXP Gains | P55: =IF(A55="","", (IF(N55="Speed of Help",2,0)) + (IF(O55="Speed of Help",-2,0)) + (IF(N55="EXP Gains",1,0)) + (IF(O55="EXP Gains",-1,0)) + (COUNTIF(H55:L55,"Helping Speed S")*1) + (COUNTIF(H55:L55,"Helping Speed M")*2) + (COUNTIF(H55:L55,"Berry Finding S")*2) + (COUNTIF(H55:L55,"Helping Bonus")*1) + (IF(O55="Ingredient Finding",0,0)) + (IF(O55="Main Skill Chance",0,0)) ) -> 1 | Q55: =IF(A55="","", (IF(N55="Ingredient Finding",2,0)) + (IF(O55="Ingredient Finding",-2,0)) + (IF(N55="EXP Gains",1,0)) + (IF(O55="EXP Gains",-1,0)) + (COUNTIF(H55:L55,"Ingredient Finder S")*1) + (COUNTIF(H55:L55,"Ingredient Finder M")*2) + (COUNTIF(H55:L55,"Inventory Up S")*0.5) + (COUNTIF(H55:L55,"Inventory Up M")*1) + (COUNTIF(H55:L55,"Inventory Up L")*1.5) + (IF(E55=F55,1,0)) + (IF(F55=G55,1,0)) ) -> 2 | R55: =IF(A55="","", (IF(N55="Main Skill Chance",2,0)) + (IF(O55="Main Skill Chance",-2,0)) + (IF(N55="EXP Gains",1,0)) + (IF(O55="EXP Gains",-1,0)) + (COUNTIF(H55:L55,"Skill Trigger S")*1) + (COUNTIF(H55:L55,"Skill Trigger M")*2) + (COUNTIF(H55:L55,"Skill Level Up S")*1) + (COUNTIF(H55:L55,"Skill Level Up M")*2) + (COUNTIF(H55:L55,"Energy Recovery Bonus")*1.5) + (COUNTIF(H55:L55,"Sleep EXP Bonus")*1) + (COUNTIF(H55:L55,"Research EXP Bonus")*1) ) -> 2 | S55: =IF(A55="","", IF(AND(P55<=1, Q55<=1, R55<=1), "Bench", IF(AND(P55>=Q55, P55>=R55), "Berry", IF(AND(Q55>=P55, Q55>=R55), "Ingredient", "Skill"))) ) -> Ingredient | T55: =IF(A55="","", MAX(P55,Q55,R55) + IF(OR(N55="Speed of Help",N55="Ingredient Finding",N55="Main Skill Chance"),1,0) + IF(N55="Neutral",0, IF(O55="Neutral",0.5,0)) + IF(B55>=10,0.5,0) ) -> 3 | U55: =IF(A55="","", IF(T55>=7, "⭐ Keep", IF(T55>=5, "📈 Level Up", IF(T55>=3, "🤔 Bench", "❌ Transfer"))) ) -> 🤔 Bench | V55: =IF(A55="","", _xlfn.TEXTJOIN("; ",TRUE, IF(A55="Pikachu","Evolve naar Raichu = snelste berry helper!",""), IF(A55="Pichu","Evolve → Pikachu → Raichu (top berry)",""), IF(A55="Eevee","Sylveon (skill) of Jolteon (berry) = top evoluties",""), IF(A55="Igglybuff","Evolve → Wigglytuff = Energy for Everyone S (top skill!)",""), IF(A55="Squirtle","Kanto starter: 2x ingrediënten + Ingredient Magnet S",""), IF(A55="Charmander","Evolve → Charizard = snelle berry+ingredient verzamelaar",""), IF(A55="Bulbasaur","Kanto starter: 2x ingrediënten + Ingredient Magnet S",""), IF(A55="Growlithe","Evolve → Arcanine = sterke all-rounder",""), IF(A55="Mareep","Evolve → Ampharos = hoge frequentie + waardevolle ingrediënten",""), IF(A55="Spheal","Evolve → Walrein = key voor Snowdrop Tundra (berry+ingr)",""), IF(A55="Riolu","Evolve → Lucario = sterke fighter",""), IF(A55="Togepi","Let op: Togekiss Metronome is onbetrouwbaar",""), IF(A55="Totodile","Evolve → Feraligatr = top berry voor Cyan Beach",""), IF(A55="Magnemite","Evolve → Magnezone = sterke skill helper",""), IF(A55="Ivysaur","Evolve → Venusaur = 2x ingrediënten specialist",""), IF(OR(N55="Neutral",O55="Neutral"),"Neutrale nature = ok maar niet ideaal",""), IF(AND(N55="Speed of Help",OR(S55="Berry",S55="Ingredient")),"Perfecte nature voor "&S55&" team!",""), IF(AND(N55="Ingredient Finding",S55="Ingredient"),"Perfecte nature voor Ingredient team!",""), IF(AND(N55="Main Skill Chance",S55="Skill"),"Perfecte nature voor Skill team!",""), IF(AND(O55="Speed of Help",S55="Berry"),"Let op: Speed of Help NEGATIEF schaadt berry-prestatie",""), IF(AND(O55="Ingredient Finding",S55="Ingredient"),"Let op: Ingredient Finding NEGATIEF schaadt ingredient-prestatie","") ))
D56: =IF(C56="","",VLOOKUP(C56,Referentie!$A$2:$B$19,2,0)) | N56: =IF(M56="","",VLOOKUP(M56,Referentie!$G$2:$I$26,2,0)) | O56: =IF(M56="","",VLOOKUP(M56,Referentie!$G$2:$I$26,3,0)) | P56: =IF(A56="","", (IF(N56="Speed of Help",2,0)) + (IF(O56="Speed of Help",-2,0)) + (IF(N56="EXP Gains",1,0)) + (IF(O56="EXP Gains",-1,0)) + (COUNTIF(H56:L56,"Helping Speed S")*1) + (COUNTIF(H56:L56,"Helping Speed M")*2) + (COUNTIF(H56:L56,"Berry Finding S")*2) + (COUNTIF(H56:L56,"Helping Bonus")*1) + (IF(O56="Ingredient Finding",0,0)) + (IF(O56="Main Skill Chance",0,0)) ) | Q56: =IF(A56="","", (IF(N56="Ingredient Finding",2,0)) + (IF(O56="Ingredient Finding",-2,0)) + (IF(N56="EXP Gains",1,0)) + (IF(O56="EXP Gains",-1,0)) + (COUNTIF(H56:L56,"Ingredient Finder S")*1) + (COUNTIF(H56:L56,"Ingredient Finder M")*2) + (COUNTIF(H56:L56,"Inventory Up S")*0.5) + (COUNTIF(H56:L56,"Inventory Up M")*1) + (COUNTIF(H56:L56,"Inventory Up L")*1.5) + (IF(E56=F56,1,0)) + (IF(F56=G56,1,0)) ) | R56: =IF(A56="","", (IF(N56="Main Skill Chance",2,0)) + (IF(O56="Main Skill Chance",-2,0)) + (IF(N56="EXP Gains",1,0)) + (IF(O56="EXP Gains",-1,0)) + (COUNTIF(H56:L56,"Skill Trigger S")*1) + (COUNTIF(H56:L56,"Skill Trigger M")*2) + (COUNTIF(H56:L56,"Skill Level Up S")*1) + (COUNTIF(H56:L56,"Skill Level Up M")*2) + (COUNTIF(H56:L56,"Energy Recovery Bonus")*1.5) + (COUNTIF(H56:L56,"Sleep EXP Bonus")*1) + (COUNTIF(H56:L56,"Research EXP Bonus")*1) ) | S56: =IF(A56="","", IF(AND(P56<=1, Q56<=1, R56<=1), "Bench", IF(AND(P56>=Q56, P56>=R56), "Berry", IF(AND(Q56>=P56, Q56>=R56), "Ingredient", "Skill"))) ) | T56: =IF(A56="","", MAX(P56,Q56,R56) + IF(OR(N56="Speed of Help",N56="Ingredient Finding",N56="Main Skill Chance"),1,0) + IF(N56="Neutral",0, IF(O56="Neutral",0.5,0)) + IF(B56>=10,0.5,0) ) | U56: =IF(A56="","", IF(T56>=7, "⭐ Keep", IF(T56>=5, "📈 Level Up", IF(T56>=3, "🤔 Bench", "❌ Transfer"))) ) | V56: =IF(A56="","", _xlfn.TEXTJOIN("; ",TRUE, IF(A56="Pikachu","Evolve naar Raichu = snelste berry helper!",""), IF(A56="Pichu","Evolve → Pikachu → Raichu (top berry)",""), IF(A56="Eevee","Sylveon (skill) of Jolteon (berry) = top evoluties",""), IF(A56="Igglybuff","Evolve → Wigglytuff = Energy for Everyone S (top skill!)",""), IF(A56="Squirtle","Kanto starter: 2x ingrediënten + Ingredient Magnet S",""), IF(A56="Charmander","Evolve → Charizard = snelle berry+ingredient verzamelaar",""), IF(A56="Bulbasaur","Kanto starter: 2x ingrediënten + Ingredient Magnet S",""), IF(A56="Growlithe","Evolve → Arcanine = sterke all-rounder",""), IF(A56="Mareep","Evolve → Ampharos = hoge frequentie + waardevolle ingrediënten",""), IF(A56="Spheal","Evolve → Walrein = key voor Snowdrop Tundra (berry+ingr)",""), IF(A56="Riolu","Evolve → Lucario = sterke fighter",""), IF(A56="Togepi","Let op: Togekiss Metronome is onbetrouwbaar",""), IF(A56="Totodile","Evolve → Feraligatr = top berry voor Cyan Beach",""), IF(A56="Magnemite","Evolve → Magnezone = sterke skill helper",""), IF(A56="Ivysaur","Evolve → Venusaur = 2x ingrediënten specialist",""), IF(OR(N56="Neutral",O56="Neutral"),"Neutrale nature = ok maar niet ideaal",""), IF(AND(N56="Speed of Help",OR(S56="Berry",S56="Ingredient")),"Perfecte nature voor "&S56&" team!",""), IF(AND(N56="Ingredient Finding",S56="Ingredient"),"Perfecte nature voor Ingredient team!",""), IF(AND(N56="Main Skill Chance",S56="Skill"),"Perfecte nature voor Skill team!",""), IF(AND(O56="Speed of Help",S56="Berry"),"Let op: Speed of Help NEGATIEF schaadt berry-prestatie",""), IF(AND(O56="Ingredient Finding",S56="Ingredient"),"Let op: Ingredient Finding NEGATIEF schaadt ingredient-prestatie","") ))
D57: =IF(C57="","",VLOOKUP(C57,Referentie!$A$2:$B$19,2,0)) | N57: =IF(M57="","",VLOOKUP(M57,Referentie!$G$2:$I$26,2,0)) | O57: =IF(M57="","",VLOOKUP(M57,Referentie!$G$2:$I$26,3,0)) | P57: =IF(A57="","", (IF(N57="Speed of Help",2,0)) + (IF(O57="Speed of Help",-2,0)) + (IF(N57="EXP Gains",1,0)) + (IF(O57="EXP Gains",-1,0)) + (COUNTIF(H57:L57,"Helping Speed S")*1) + (COUNTIF(H57:L57,"Helping Speed M")*2) + (COUNTIF(H57:L57,"Berry Finding S")*2) + (COUNTIF(H57:L57,"Helping Bonus")*1) + (IF(O57="Ingredient Finding",0,0)) + (IF(O57="Main Skill Chance",0,0)) ) | Q57: =IF(A57="","", (IF(N57="Ingredient Finding",2,0)) + (IF(O57="Ingredient Finding",-2,0)) + (IF(N57="EXP Gains",1,0)) + (IF(O57="EXP Gains",-1,0)) + (COUNTIF(H57:L57,"Ingredient Finder S")*1) + (COUNTIF(H57:L57,"Ingredient Finder M")*2) + (COUNTIF(H57:L57,"Inventory Up S")*0.5) + (COUNTIF(H57:L57,"Inventory Up M")*1) + (COUNTIF(H57:L57,"Inventory Up L")*1.5) + (IF(E57=F57,1,0)) + (IF(F57=G57,1,0)) ) | R57: =IF(A57="","", (IF(N57="Main Skill Chance",2,0)) + (IF(O57="Main Skill Chance",-2,0)) + (IF(N57="EXP Gains",1,0)) + (IF(O57="EXP Gains",-1,0)) + (COUNTIF(H57:L57,"Skill Trigger S")*1) + (COUNTIF(H57:L57,"Skill Trigger M")*2) + (COUNTIF(H57:L57,"Skill Level Up S")*1) + (COUNTIF(H57:L57,"Skill Level Up M")*2) + (COUNTIF(H57:L57,"Energy Recovery Bonus")*1.5) + (COUNTIF(H57:L57,"Sleep EXP Bonus")*1) + (COUNTIF(H57:L57,"Research EXP Bonus")*1) ) | S57: =IF(A57="","", IF(AND(P57<=1, Q57<=1, R57<=1), "Bench", IF(AND(P57>=Q57, P57>=R57), "Berry", IF(AND(Q57>=P57, Q57>=R57), "Ingredient", "Skill"))) ) | T57: =IF(A57="","", MAX(P57,Q57,R57) + IF(OR(N57="Speed of Help",N57="Ingredient Finding",N57="Main Skill Chance"),1,0) + IF(N57="Neutral",0, IF(O57="Neutral",0.5,0)) + IF(B57>=10,0.5,0) ) | U57: =IF(A57="","", IF(T57>=7, "⭐ Keep", IF(T57>=5, "📈 Level Up", IF(T57>=3, "🤔 Bench", "❌ Transfer"))) ) | V57: =IF(A57="","", _xlfn.TEXTJOIN("; ",TRUE, IF(A57="Pikachu","Evolve naar Raichu = snelste berry helper!",""), IF(A57="Pichu","Evolve → Pikachu → Raichu (top berry)",""), IF(A57="Eevee","Sylveon (skill) of Jolteon (berry) = top evoluties",""), IF(A57="Igglybuff","Evolve → Wigglytuff = Energy for Everyone S (top skill!)",""), IF(A57="Squirtle","Kanto starter: 2x ingrediënten + Ingredient Magnet S",""), IF(A57="Charmander","Evolve → Charizard = snelle berry+ingredient verzamelaar",""), IF(A57="Bulbasaur","Kanto starter: 2x ingrediënten + Ingredient Magnet S",""), IF(A57="Growlithe","Evolve → Arcanine = sterke all-rounder",""), IF(A57="Mareep","Evolve → Ampharos = hoge frequentie + waardevolle ingrediënten",""), IF(A57="Spheal","Evolve → Walrein = key voor Snowdrop Tundra (berry+ingr)",""), IF(A57="Riolu","Evolve → Lucario = sterke fighter",""), IF(A57="Togepi","Let op: Togekiss Metronome is onbetrouwbaar",""), IF(A57="Totodile","Evolve → Feraligatr = top berry voor Cyan Beach",""), IF(A57="Magnemite","Evolve → Magnezone = sterke skill helper",""), IF(A57="Ivysaur","Evolve → Venusaur = 2x ingrediënten specialist",""), IF(OR(N57="Neutral",O57="Neutral"),"Neutrale nature = ok maar niet ideaal",""), IF(AND(N57="Speed of Help",OR(S57="Berry",S57="Ingredient")),"Perfecte nature voor "&S57&" team!",""), IF(AND(N57="Ingredient Finding",S57="Ingredient"),"Perfecte nature voor Ingredient team!",""), IF(AND(N57="Main Skill Chance",S57="Skill"),"Perfecte nature voor Skill team!",""), IF(AND(O57="Speed of Help",S57="Berry"),"Let op: Speed of Help NEGATIEF schaadt berry-prestatie",""), IF(AND(O57="Ingredient Finding",S57="Ingredient"),"Let op: Ingredient Finding NEGATIEF schaadt ingredient-prestatie","") ))
